Workbook

Sheet Summary
A1: Climate metrics summary - general account corporate bond book (SYNTHETIC portfolio)
A2: B-15 style metrics: financed emissions (PCAF), carbon footprint, WACI vs benchmark, carbon-price stress. Emission factors: Statistics Canada tables 38-10-0097-01 and 36-10-0488-01.
A3: Reporting year | B3: =Inputs!B3
A4: Holdings | B4: =COUNTA(Holdings!A2:A301)
A5: Book value ($M CAD) | B5: =SUM(Holdings!F2:F301)
A6: Book ties to stated total | B6: =IF(ABS(B5-Inputs!B4)<0.05,"PASS","FAIL")
A7: Financed emissions (tCO2e) | B7: ='Financed Emissions'!Q27
A8: Carbon footprint (tCO2e per $M invested) | B8: =WACI!B31
A9: Portfolio WACI (tCO2e per $M revenue) | B9: ='Benchmark Comparison'!B29
A10: Benchmark WACI (tCO2e per $M revenue) | B10: ='Benchmark Comparison'!B30
A11: Portfolio WACI vs benchmark | B11: ='Benchmark Comparison'!B31
A12: Weighted PCAF data-quality score (1 best - 5 worst) | B12: ='Financed Emissions'!S27
A13: Share of book at PCAF score 5 | B13: =SUMIFS('Financed Emissions'!C5:C304,'Financed Emissions'!J5:J304,5)/B5
A14: Portfolio-sector share of StatCan industry emissions | B14: =SUMIFS('Emission Factors'!C:C,'Emission Factors'!B:B,B3)/INDEX('StatCan Totals'!B:B,MATCH(B3,'StatCan Totals'!A:A,0))
A15: StatCan reconciliation (all years) | B15: =Reconciliation!B21
A18: Rank | B18: Top sectors by financed emissions | C18: Financed emissions (tCO2e) | D18: Share of total
A19: 1 | B19: =INDEX('Financed Emissions'!$N$5:$N$26,MATCH(C19,'Financed Emissions'!$Q$5:$Q$26,0)) | C19: =LARGE('Financed Emissions'!$Q$5:$Q$26,A19) | D19: =C19/'Financed Emissions'!$Q$27
A20: 2 | B20: =INDEX('Financed Emissions'!$N$5:$N$26,MATCH(C20,'Financed Emissions'!$Q$5:$Q$26,0)) | C20: =LARGE('Financed Emissions'!$Q$5:$Q$26,A20) | D20: =C20/'Financed Emissions'!$Q$27
A21: 3 | B21: =INDEX('Financed Emissions'!$N$5:$N$26,MATCH(C21,'Financed Emissions'!$Q$5:$Q$26,0)) | C21: =LARGE('Financed Emissions'!$Q$5:$Q$26,A21) | D21: =C21/'Financed Emissions'!$Q$27
A22: 4 | B22: =INDEX('Financed Emissions'!$N$5:$N$26,MATCH(C22,'Financed Emissions'!$Q$5:$Q$26,0)) | C22: =LARGE('Financed Emissions'!$Q$5:$Q$26,A22) | D22: =C22/'Financed Emissions'!$Q$27
A23: 5 | B23: =INDEX('Financed Emissions'!$N$5:$N$26,MATCH(C23,'Financed Emissions'!$Q$5:$Q$26,0)) | C23: =LARGE('Financed Emissions'!$Q$5:$Q$26,A23) | D23: =C23/'Financed Emissions'!$Q$27
A26: Scenario | B26: Carbon cost in headline year ($M CAD) | C26: Share of holdings
A27: =Inputs!A9 | B27: =INDEX('Carbon Price Scenarios'!$B$11:$H$13,1,MATCH(Inputs!$B$5,'Carbon Price Scenarios'!$B$4:$H$4,0)) | C27: =B27/$B$5
A28: =Inputs!A10 | B28: =INDEX('Carbon Price Scenarios'!$B$11:$H$13,2,MATCH(Inputs!$B$5,'Carbon Price Scenarios'!$B$4:$H$4,0)) | C28: =B28/$B$5
A29: =Inputs!A11 | B29: =INDEX('Carbon Price Scenarios'!$B$11:$H$13,3,MATCH(Inputs!$B$5,'Carbon Price Scenarios'!$B$4:$H$4,0)) | C29: =B29/$B$5
A31: Portfolio is synthetic (no real issuers). Emission factors are economy-wide sector averages (PCAF score 4-5); issuer-reported emissions would replace them where available.

Sheet Inputs
A1: Inputs and assumptions
A2: Yellow cells are inputs: change them and every other tab recalculates.
A3: Reporting year (emission factor vintage) | B3: 2022
A4: Stated book total ($M CAD) | B4: 12000
A5: Headline scenario year | B5: 2030
A7: Carbon price paths ($CAD per tCO2e, nominal)
A8: Scenario | B8: 2024 | C8: 2025 | D8: 2026 | E8: 2027 | F8: 2028 | G8: 2029 | H8: 2030 | I8: Free allocation share | J8: Description
A9: Current federal policy | B9: 80 | C9: 95 | D9: 110 | E9: 125 | F9: 140 | G9: 155 | H9: 170 | I9: 0.8 | J9: Federal OBPS benchmark price rising $15/t a year to $170/t in 2030; large emitters pay only on emissions above their output-based standard
A10: Net-zero shadow price | B10: 150 | C10: 175 | D10: 200 | E10: 225 | F10: 250 | G10: 275 | H10: 300 | I10: 0.5 | J10: Illustrative internal shadow price consistent with a net-zero 2050 pathway; less free allocation
A11: Delayed transition | B11: 80 | C11: 80 | D11: 80 | E11: 80 | F11: 140 | G11: 200 | H11: 260 | I11: 0.8 | J11: Illustrative path: price frozen to 2027 then a sharp catch-up toward net-zero levels
A13: Revenue-to-EVIC proxy by sector (used when issuer revenue is not on file, PCAF score 5)
A14: Portfolio sector | B14: Revenue / EVIC
A15: Oil & Gas Producers | B15: 0.55
A16: Petroleum Refining | B16: 1.4
A17: Pipelines | B17: 0.25
A18: Electric Utilities | B18: 0.3
A19: Gas Distribution & Water | B19: 0.35
A20: Mining & Quarrying | B20: 0.5
A21: Cement & Building Materials | B21: 0.7
A22: Metals & Steel | B22: 0.9
A23: Chemicals & Plastics | B23: 0.8
A24: Forest & Paper Products | B24: 0.85
A25: Agriculture & Food | B25: 1.1
A26: Airlines | B26: 0.9
... A36: Business & Consumer Services | B36: 0.6

Sheet Emission Factors
A1: Sector emission factors (tCO2e per $M CAD of gross output)
A2: Emissions and output are SUMIFS over the StatCan sheets by portfolio sector and year.
A4: Portfolio sector | B4: Year | C4: Emissions (kt CO2e) | D4: Gross output ($M) | E4: Emission factor (t/$M) | G4: Portfolio sector | H4: EF in reporting year (t/$M) | I4: Output in reporting year ($M) | J4: Emissions in reporting year (kt)
A5: Oil & Gas Producers | B5: 2009 | C5: =SUMIFS('StatCan GHG'!$D$2:$D$1692,'StatCan GHG'!$E$2:$E$1692,A5,'StatCan GHG'!$A$2:$A$1692,B5) | D5: =SUMIFS('StatCan Output'!$D$2:$D$1504,'StatCan Output'!$E$2:$E$1504,A5,'StatCan Output'!$A$2:$A$1504,B5) | E5: =IF(D5>0,C5*1000/D5,0) | G5: Oil & Gas Producers | H5: =SUMIFS($E$5:$E$312,$A$5:$A$312,G5,$B$5:$B$312,Inputs!$B$3) | I5: =SUMIFS($D$5:$D$312,$A$5:$A$312,G5,$B$5:$B$312,Inputs!$B$3) | J5: =SUMIFS($C$5:$C$312,$A$5:$A$312,G5,$B$5:$B$312,Inputs!$B$3)
A6: Oil & Gas Producers | B6: 2010 | C6: =SUMIFS('StatCan GHG'!$D$2:$D$1692,'StatCan GHG'!$E$2:$E$1692,A6,'StatCan GHG'!$A$2:$A$1692,B6) | D6: =SUMIFS('StatCan Output'!$D$2:$D$1504,'StatCan Output'!$E$2:$E$1504,A6,'StatCan Output'!$A$2:$A$1504,B6) | E6: =IF(D6>0,C6*1000/D6,0) | G6: Petroleum Refining | H6: =SUMIFS($E$5:$E$312,$A$5:$A$312,G6,$B$5:$B$312,Inputs!$B$3) | I6: =SUMIFS($D$5:$D$312,$A$5:$A$312,G6,$B$5:$B$312,Inputs!$B$3) | J6: =SUMIFS($C$5:$C$312,$A$5:$A$312,G6,$B$5:$B$312,Inputs!$B$3)
A7: Oil & Gas Producers | B7: 2011 | C7: =SUMIFS('StatCan GHG'!$D$2:$D$1692,'StatCan GHG'!$E$2:$E$1692,A7,'StatCan GHG'!$A$2:$A$1692,B7) | D7: =SUMIFS('StatCan Output'!$D$2:$D$1504,'StatCan Output'!$E$2:$E$1504,A7,'StatCan Output'!$A$2:$A$1504,B7) | E7: =IF(D7>0,C7*1000/D7,0) | G7: Pipelines | H7: =SUMIFS($E$5:$E$312,$A$5:$A$312,G7,$B$5:$B$312,Inputs!$B$3) | I7: =SUMIFS($D$5:$D$312,$A$5:$A$312,G7,$B$5:$B$312,Inputs!$B$3) | J7: =SUMIFS($C$5:$C$312,$A$5:$A$312,G7,$B$5:$B$312,Inputs!$B$3)
A8: Oil & Gas Producers | B8: 2012 | C8: =SUMIFS('StatCan GHG'!$D$2:$D$1692,'StatCan GHG'!$E$2:$E$1692,A8,'StatCan GHG'!$A$2:$A$1692,B8) | D8: =SUMIFS('StatCan Output'!$D$2:$D$1504,'StatCan Output'!$E$2:$E$1504,A8,'StatCan Output'!$A$2:$A$1504,B8) | E8: =IF(D8>0,C8*1000/D8,0) | G8: Electric Utilities | H8: =SUMIFS($E$5:$E$312,$A$5:$A$312,G8,$B$5:$B$312,Inputs!$B$3) | I8: =SUMIFS($D$5:$D$312,$A$5:$A$312,G8,$B$5:$B$312,Inputs!$B$3) | J8: =SUMIFS($C$5:$C$312,$A$5:$A$312,G8,$B$5:$B$312,Inputs!$B$3)
A9: Oil & Gas Producers | B9: 2013 | C9: =SUMIFS('StatCan GHG'!$D$2:$D$1692,'StatCan GHG'!$E$2:$E$1692,A9,'StatCan GHG'!$A$2:$A$1692,B9) | D9: =SUMIFS('StatCan Output'!$D$2:$D$1504,'StatCan Output'!$E$2:$E$1504,A9,'StatCan Output'!$A$2:$A$1504,B9) | E9: =IF(D9>0,C9*1000/D9,0) | G9: Gas Distribution & Water | H9: =SUMIFS($E$5:$E$312,$A$5:$A$312,G9,$B$5:$B$312,Inputs!$B$3) | I9: =SUMIFS($D$5:$D$312,$A$5:$A$312,G9,$B$5:$B$312,Inputs!$B$3) | J9: =SUMIFS($C$5:$C$312,$A$5:$A$312,G9,$B$5:$B$312,Inputs!$B$3)
A10: Oil & Gas Producers | B10: 2014 | C10: =SUMIFS('StatCan GHG'!$D$2:$D$1692,'StatCan GHG'!$E$2:$E$1692,A10,'StatCan GHG'!$A$2:$A$1692,B10) | D10: =SUMIFS('StatCan Output'!$D$2:$D$1504,'StatCan Output'!$E$2:$E$1504,A10,'StatCan Output'!$A$2:$A$1504,B10) | E10: =IF(D10>0,C10*1000/D10,0) | G10: Mining & Quarrying | H10: =SUMIFS($E$5:$E$312,$A$5:$A$312,G10,$B$5:$B$312,Inputs!$B$3) | I10: =SUMIFS($D$5:$D$312,$A$5:$A$312,G10,$B$5:$B$312,Inputs!$B$3) | J10: =SUMIFS($C$5:$C$312,$A$5:$A$312,G10,$B$5:$B$312,Inputs!$B$3)
A11: Oil & Gas Producers | B11: 2015 | C11: =SUMIFS('StatCan GHG'!$D$2:$D$1692,'StatCan GHG'!$E$2:$E$1692,A11,'StatCan GHG'!$A$2:$A$1692,B11) | D11: =SUMIFS('StatCan Output'!$D$2:$D$1504,'StatCan Output'!$E$2:$E$1504,A11,'StatCan Output'!$A$2:$A$1504,B11) | E11: =IF(D11>0,C11*1000/D11,0) | G11: Cement & Building Materials | H11: =SUMIFS($E$5:$E$312,$A$5:$A$312,G11,$B$5:$B$312,Inputs!$B$3) | I11: =SUMIFS($D$5:$D$312,$A$5:$A$312,G11,$B$5:$B$312,Inputs!$B$3) | J11: =SUMIFS($C$5:$C$312,$A$5:$A$312,G11,$B$5:$B$312,Inputs!$B$3)
A12: Oil & Gas Producers | B12: 2016 | C12: =SUMIFS('StatCan GHG'!$D$2:$D$1692,'StatCan GHG'!$E$2:$E$1692,A12,'StatCan GHG'!$A$2:$A$1692,B12) | D12: =SUMIFS('StatCan Output'!$D$2:$D$1504,'StatCan Output'!$E$2:$E$1504,A12,'StatCan Output'!$A$2:$A$1504,B12) | E12: =IF(D12>0,C12*1000/D12,0) | G12: Metals & Steel | H12: =SUMIFS($E$5:$E$312,$A$5:$A$312,G12,$B$5:$B$312,Inputs!$B$3) | I12: =SUMIFS($D$5:$D$312,$A$5:$A$312,G12,$B$5:$B$312,Inputs!$B$3) | J12: =SUMIFS($C$5:$C$312,$A$5:$A$312,G12,$B$5:$B$312,Inputs!$B$3)
A13: Oil & Gas Producers | B13: 2017 | C13: =SUMIFS('StatCan GHG'!$D$2:$D$1692,'StatCan GHG'!$E$2:$E$1692,A13,'StatCan GHG'!$A$2:$A$1692,B13) | D13: =SUMIFS('StatCan Output'!$D$2:$D$1504,'StatCan Output'!$E$2:$E$1504,A13,'StatCan Output'!$A$2:$A$1504,B13) | E13: =IF(D13>0,C13*1000/D13,0) | G13: Chemicals & Plastics | H13: =SUMIFS($E$5:$E$312,$A$5:$A$312,G13,$B$5:$B$312,Inputs!$B$3) | I13: =SUMIFS($D$5:$D$312,$A$5:$A$312,G13,$B$5:$B$312,Inputs!$B$3) | J13: =SUMIFS($C$5:$C$312,$A$5:$A$312,G13,$B$5:$B$312,Inputs!$B$3)
A14: Oil & Gas Producers | B14: 2018 | C14: =SUMIFS('StatCan GHG'!$D$2:$D$1692,'StatCan GHG'!$E$2:$E$1692,A14,'StatCan GHG'!$A$2:$A$1692,B14) | D14: =SUMIFS('StatCan Output'!$D$2:$D$1504,'StatCan Output'!$E$2:$E$1504,A14,'StatCan Output'!$A$2:$A$1504,B14) | E14: =IF(D14>0,C14*1000/D14,0) | G14: Forest & Paper Products | H14: =SUMIFS($E$5:$E$312,$A$5:$A$312,G14,$B$5:$B$312,Inputs!$B$3) | I14: =SUMIFS($D$5:$D$312,$A$5:$A$312,G14,$B$5:$B$312,Inputs!$B$3) | J14: =SUMIFS($C$5:$C$312,$A$5:$A$312,G14,$B$5:$B$312,Inputs!$B$3)
A15: Oil & Gas Producers | B15: 2019 | C15: =SUMIFS('StatCan GHG'!$D$2:$D$1692,'StatCan GHG'!$E$2:$E$1692,A15,'StatCan GHG'!$A$2:$A$1692,B15) | D15: =SUMIFS('StatCan Output'!$D$2:$D$1504,'StatCan Output'!$E$2:$E$1504,A15,'StatCan Output'!$A$2:$A$1504,B15) | E15: =IF(D15>0,C15*1000/D15,0) | G15: Agriculture & Food | H15: =SUMIFS($E$5:$E$312,$A$5:$A$312,G15,$B$5:$B$312,Inputs!$B$3) | I15: =SUMIFS($D$5:$D$312,$A$5:$A$312,G15,$B$5:$B$312,Inputs!$B$3) | J15: =SUMIFS($C$5:$C$312,$A$5:$A$312,G15,$B$5:$B$312,Inputs!$B$3)
A16: Oil & Gas Producers | B16: 2020 | C16: =SUMIFS('StatCan GHG'!$D$2:$D$1692,'StatCan GHG'!$E$2:$E$1692,A16,'StatCan GHG'!$A$2:$A$1692,B16) | D16: =SUMIFS('StatCan Output'!$D$2:$D$1504,'StatCan Output'!$E$2:$E$1504,A16,'StatCan Output'!$A$2:$A$1504,B16) | E16: =IF(D16>0,C16*1000/D16,0) | G16: Airlines | H16: =SUMIFS($E$5:$E$312,$A$5:$A$312,G16,$B$5:$B$312,Inputs!$B$3) | I16: =SUMIFS($D$5:$D$312,$A$5:$A$312,G16,$B$5:$B$312,Inputs!$B$3) | J16: =SUMIFS($C$5:$C$312,$A$5:$A$312,G16,$B$5:$B$312,Inputs!$B$3)
... A26: Petroleum Refining | B26: 2016 | C26: =SUMIFS('StatCan GHG'!$D$2:$D$1692,'StatCan GHG'!$E$2:$E$1692,A26,'StatCan GHG'!$A$2:$A$1692,B26) | D26: =SUMIFS('StatCan Output'!$D$2:$D$1504,'StatCan Output'!$E$2:$E$1504,A26,'StatCan Output'!$A$2:$A$1504,B26) | E26: =IF(D26>0,C26*1000/D26,0) | G26: Business & Consumer Services | H26: =SUMIFS($E$5:$E$312,$A$5:$A$312,G26,$B$5:$B$312,Inputs!$B$3) | I26: =SUMIFS($D$5:$D$312,$A$5:$A$312,G26,$B$5:$B$312,Inputs!$B$3) | J26: =SUMIFS($C$5:$C$312,$A$5:$A$312,G26,$B$5:$B$312,Inputs!$B$3)
A27: Petroleum Refining | B27: 2017 | C27: =SUMIFS('StatCan GHG'!$D$2:$D$1692,'StatCan GHG'!$E$2:$E$1692,A27,'StatCan GHG'!$A$2:$A$1692,B27) | D27: =SUMIFS('StatCan Output'!$D$2:$D$1504,'StatCan Output'!$E$2:$E$1504,A27,'StatCan Output'!$A$2:$A$1504,B27) | E27: =IF(D27>0,C27*1000/D27,0)
A28: Petroleum Refining | B28: 2018 | C28: =SUMIFS('StatCan GHG'!$D$2:$D$1692,'StatCan GHG'!$E$2:$E$1692,A28,'StatCan GHG'!$A$2:$A$1692,B28) | D28: =SUMIFS('StatCan Output'!$D$2:$D$1504,'StatCan Output'!$E$2:$E$1504,A28,'StatCan Output'!$A$2:$A$1504,B28) | E28: =IF(D28>0,C28*1000/D28,0)
A29: Petroleum Refining | B29: 2019 | C29: =SUMIFS('StatCan GHG'!$D$2:$D$1692,'StatCan GHG'!$E$2:$E$1692,A29,'StatCan GHG'!$A$2:$A$1692,B29) | D29: =SUMIFS('StatCan Output'!$D$2:$D$1504,'StatCan Output'!$E$2:$E$1504,A29,'StatCan Output'!$A$2:$A$1504,B29) | E29: =IF(D29>0,C29*1000/D29,0)
A30: Petroleum Refining | B30: 2020 | C30: =SUMIFS('StatCan GHG'!$D$2:$D$1692,'StatCan GHG'!$E$2:$E$1692,A30,'StatCan GHG'!$A$2:$A$1692,B30) | D30: =SUMIFS('StatCan Output'!$D$2:$D$1504,'StatCan Output'!$E$2:$E$1504,A30,'StatCan Output'!$A$2:$A$1504,B30) | E30: =IF(D30>0,C30*1000/D30,0)
A31: Petroleum Refining | B31: 2021 | C31: =SUMIFS('StatCan GHG'!$D$2:$D$1692,'StatCan GHG'!$E$2:$E$1692,A31,'StatCan GHG'!$A$2:$A$1692,B31) | D31: =SUMIFS('StatCan Output'!$D$2:$D$1504,'StatCan Output'!$E$2:$E$1504,A31,'StatCan Output'!$A$2:$A$1504,B31) | E31: =IF(D31>0,C31*1000/D31,0)
A32: Petroleum Refining | B32: 2022 | C32: =SUMIFS('StatCan GHG'!$D$2:$D$1692,'StatCan GHG'!$E$2:$E$1692,A32,'StatCan GHG'!$A$2:$A$1692,B32) | D32: =SUMIFS('StatCan Output'!$D$2:$D$1504,'StatCan Output'!$E$2:$E$1504,A32,'StatCan Output'!$A$2:$A$1504,B32) | E32: =IF(D32>0,C32*1000/D32,0)
A33: Pipelines | B33: 2009 | C33: =SUMIFS('StatCan GHG'!$D$2:$D$1692,'StatCan GHG'!$E$2:$E$1692,A33,'StatCan GHG'!$A$2:$A$1692,B33) | D33: =SUMIFS('StatCan Output'!$D$2:$D$1504,'StatCan Output'!$E$2:$E$1504,A33,'StatCan Output'!$A$2:$A$1504,B33) | E33: =IF(D33>0,C33*1000/D33,0)
A34: Pipelines | B34: 2010 | C34: =SUMIFS('StatCan GHG'!$D$2:$D$1692,'StatCan GHG'!$E$2:$E$1692,A34,'StatCan GHG'!$A$2:$A$1692,B34) | D34: =SUMIFS('StatCan Output'!$D$2:$D$1504,'StatCan Output'!$E$2:$E$1504,A34,'StatCan Output'!$A$2:$A$1504,B34) | E34: =IF(D34>0,C34*1000/D34,0)
A35: Pipelines | B35: 2011 | C35: =SUMIFS('StatCan GHG'!$D$2:$D$1692,'StatCan GHG'!$E$2:$E$1692,A35,'StatCan GHG'!$A$2:$A$1692,B35) | D35: =SUMIFS('StatCan Output'!$D$2:$D$1504,'StatCan Output'!$E$2:$E$1504,A35,'StatCan Output'!$A$2:$A$1504,B35) | E35: =IF(D35>0,C35*1000/D35,0)
A36: Pipelines | B36: 2012 | C36: =SUMIFS('StatCan GHG'!$D$2:$D$1692,'StatCan GHG'!$E$2:$E$1692,A36,'StatCan GHG'!$A$2:$A$1692,B36) | D36: =SUMIFS('StatCan Output'!$D$2:$D$1504,'StatCan Output'!$E$2:$E$1504,A36,'StatCan Output'!$A$2:$A$1504,B36) | E36: =IF(D36>0,C36*1000/D36,0)
A37: Pipelines | B37: 2013 | C37: =SUMIFS('StatCan GHG'!$D$2:$D$1692,'StatCan GHG'!$E$2:$E$1692,A37,'StatCan GHG'!$A$2:$A$1692,B37) | D37: =SUMIFS('StatCan Output'!$D$2:$D$1504,'StatCan Output'!$E$2:$E$1504,A37,'StatCan Output'!$A$2:$A$1504,B37) | E37: =IF(D37>0,C37*1000/D37,0)
A38: Pipelines | B38: 2014 | C38: =SUMIFS('StatCan GHG'!$D$2:$D$1692,'StatCan GHG'!$E$2:$E$1692,A38,'StatCan GHG'!$A$2:$A$1692,B38) | D38: =SUMIFS('StatCan Output'!$D$2:$D$1504,'StatCan Output'!$E$2:$E$1504,A38,'StatCan Output'!$A$2:$A$1504,B38) | E38: =IF(D38>0,C38*1000/D38,0)
... A312: Business & Consumer Services | B312: 2022 | C312: =SUMIFS('StatCan GHG'!$D$2:$D$1692,'StatCan GHG'!$E$2:$E$1692,A312,'StatCan GHG'!$A$2:$A$1692,B312) | D312: =SUMIFS('StatCan Output'!$D$2:$D$1504,'StatCan Output'!$E$2:$E$1504,A312,'StatCan Output'!$A$2:$A$1504,B312) | E312: =IF(D312>0,C312*1000/D312,0)

Sheet Crosswalk
A1: StatCan code | B1: StatCan industry (IOIC) | C1: Portfolio sector
A2: BS111CL | B2: Cannabis production (licensed) | C2: Agriculture & Food
A3: BS111CU | B3: Cannabis production (unlicensed) | C3: Agriculture & Food
A4: BS11400 | B4: Fishing, hunting and trapping | C4: Agriculture & Food
A5: BS11500 | B5: Support activities for agriculture and forestry | C5: Agriculture & Food
A6: BS11A00 | B6: Crop and animal production | C6: Agriculture & Food
A7: BS11B00 | B7: Crop and animal production (except cannabis) | C7: Agriculture & Food
A8: BS31110 | B8: Animal food manufacturing | C8: Agriculture & Food
A9: BS31130 | B9: Sugar and confectionery product manufacturing | C9: Agriculture & Food
A10: BS31140 | B10: Fruit and vegetable preserving and specialty food manufacturing | C10: Agriculture & Food
A11: BS31150 | B11: Dairy product manufacturing | C11: Agriculture & Food
A12: BS31160 | B12: Meat product manufacturing | C12: Agriculture & Food
... A125: BS49A00 | B125: Postal service and couriers and messengers | C125: Trucking, Marine & Logistics

Sheet Holdings
A1: Holding ID | B1: Issuer (SYNTHETIC) | C1: Portfolio sector | D1: Instrument | E1: Rating | F1: Outstanding ($M CAD) | G1: Issuer EVIC ($M) | H1: Issuer revenue ($M, blank = not on file)
A2: H001 | B2: SYN Oil & Gas Producers 01 Corp | C2: Oil & Gas Producers | D2: Public corporate bond | E2: BBB | F2: 37.1 | G2: 3368
A3: H002 | B3: SYN Oil & Gas Producers 02 Corp | C3: Oil & Gas Producers | D3: Private placement | E3: A | F3: 65.4 | G3: 24385
A4: H003 | B4: SYN Oil & Gas Producers 03 Corp | C4: Oil & Gas Producers | D4: Public corporate bond | E4: A | F4: 11.5 | G4: 457
A5: H004 | B5: SYN Oil & Gas Producers 04 Corp | C5: Oil & Gas Producers | D5: Public corporate bond | E5: A | F5: 12.3 | G5: 697
A6: H005 | B6: SYN Oil & Gas Producers 05 Corp | C6: Oil & Gas Producers | D6: Private placement | E6: BBB | F6: 21.9 | G6: 926
A7: H006 | B7: SYN Oil & Gas Producers 06 Corp | C7: Oil & Gas Producers | D7: Public corporate bond | E7: A | F7: 78.1 | G7: 2705
A8: H007 | B8: SYN Oil & Gas Producers 07 Corp | C8: Oil & Gas Producers | D8: Public corporate bond | E8: BBB | F8: 11.5 | G8: 1374
A9: H008 | B9: SYN Oil & Gas Producers 08 Corp | C9: Oil & Gas Producers | D9: Private placement | E9: BBB | F9: 76.7 | G9: 22687
A10: H009 | B10: SYN Oil & Gas Producers 09 Corp | C10: Oil & Gas Producers | D10: Private placement | E10: A | F10: 54.4 | G10: 2131
A11: H010 | B11: SYN Oil & Gas Producers 10 Corp | C11: Oil & Gas Producers | D11: Public corporate bond | E11: BBB | F11: 32.1 | G11: 1490
A12: H011 | B12: SYN Oil & Gas Producers 11 Corp | C12: Oil & Gas Producers | D12: Infrastructure debt | E12: BBB | F12: 9.8 | G12: 280
A13: H012 | B13: SYN Oil & Gas Producers 12 Corp | C13: Oil & Gas Producers | D13: Public corporate bond | E13: BBB | F13: 29.5 | G13: 2304
A14: H013 | B14: SYN Oil & Gas Producers 13 Corp | C14: Oil & Gas Producers | D14: Public corporate bond | E14: BBB | F14: 36.5 | G14: 9885 | H14: 4435
A15: H014 | B15: SYN Oil & Gas Producers 14 Corp | C15: Oil & Gas Producers | D15: Public corporate bond | E15: A | F15: 34.7 | G15: 2122
A16: H015 | B16: SYN Oil & Gas Producers 15 Corp | C16: Oil & Gas Producers | D16: Infrastructure debt | E16: A | F16: 12.4 | G16: 376
A17: H016 | B17: SYN Oil & Gas Producers 16 Corp | C17: Oil & Gas Producers | D17: Infrastructure debt | E17: BBB | F17: 93.9 | G17: 4689 | H17: 2888
A18: H017 | B18: SYN Oil & Gas Producers 17 Corp | C18: Oil & Gas Producers | D18: Private placement | E18: AA | F18: 74.3 | G18: 4820
A19: H018 | B19: SYN Oil & Gas Producers 18 Corp | C19: Oil & Gas Producers | D19: Private placement | E19: BBB | F19: 28 | G19: 1312 | H19: 863
A20: H019 | B20: SYN Petroleum Refining 01 Corp | C20: Petroleum Refining | D20: Private placement | E20: BBB | F20: 98.2 | G20: 8532
A21: H020 | B21: SYN Petroleum Refining 02 Corp | C21: Petroleum Refining | D21: Public corporate bond | E21: A | F21: 19.2 | G21: 517
A22: H021 | B22: SYN Petroleum Refining 03 Corp | C22: Petroleum Refining | D22: Public corporate bond | E22: BBB | F22: 18 | G22: 1542
A23: H022 | B23: SYN Petroleum Refining 04 Corp | C23: Petroleum Refining | D23: Public corporate bond | E23: BBB | F23: 20.2 | G23: 613 | H23: 887
A24: H023 | B24: SYN Petroleum Refining 05 Corp | C24: Petroleum Refining | D24: Private placement | E24: A | F24: 24.4 | G24: 847
A25: H024 | B25: SYN Pipelines 01 Corp | C25: Pipelines | D25: Private placement | E25: BBB | F25: 12.8 | G25: 479
A26: H025 | B26: SYN Pipelines 02 Corp | C26: Pipelines | D26: Public corporate bond | E26: BBB | F26: 19.9 | G26: 9382 | H26: 2202
A27: H026 | B27: SYN Pipelines 03 Corp | C27: Pipelines | D27: Infrastructure debt | E27: A | F27: 13.5 | G27: 420 | H27: 115
A28: H027 | B28: SYN Pipelines 04 Corp | C28: Pipelines | D28: Public corporate bond | E28: BBB | F28: 137.7 | G28: 7124
A29: H028 | B29: SYN Pipelines 05 Corp | C29: Pipelines | D29: Infrastructure debt | E29: AA | F29: 31.1 | G29: 956 | H29: 178
A30: H029 | B30: SYN Pipelines 06 Corp | C30: Pipelines | D30: Private placement | E30: AA | F30: 23 | G30: 1720
A31: H030 | B31: SYN Pipelines 07 Corp | C31: Pipelines | D31: Public corporate bond | E31: A | F31: 64.6 | G31: 4069 | H31: 1579
A32: H031 | B32: SYN Pipelines 08 Corp | C32: Pipelines | D32: Public corporate bond | E32: A | F32: 31.8 | G32: 910
A33: H032 | B33: SYN Pipelines 09 Corp | C33: Pipelines | D33: Infrastructure debt | E33: A | F33: 28.6 | G33: 978
A34: H033 | B34: SYN Pipelines 10 Corp | C34: Pipelines | D34: Private placement | E34: AA | F34: 6.9 | G34: 297
A35: H034 | B35: SYN Pipelines 11 Corp | C35: Pipelines | D35: Public corporate bond | E35: A | F35: 24.3 | G35: 2014
A36: H035 | B36: SYN Pipelines 12 Corp | C36: Pipelines | D36: Infrastructure debt | E36: BBB | F36: 22.1 | G36: 924
A37: H036 | B37: SYN Pipelines 13 Corp | C37: Pipelines | D37: Private placement | E37: A | F37: 26.9 | G37: 1561
A38: H037 | B38: SYN Pipelines 14 Corp | C38: Pipelines | D38: Public corporate bond | E38: A | F38: 34 | G38: 1364 | H38: 482
A39: H038 | B39: SYN Pipelines 15 Corp | C39: Pipelines | D39: Private placement | E39: BBB | F39: 34.6 | G39: 8107 | H39: 2550
A40: H039 | B40: SYN Pipelines 16 Corp | C40: Pipelines | D40: Public corporate bond | E40: AA | F40: 34.9 | G40: 1816 | H40: 378
...

Sheet Financed Emissions
A1: PCAF financed emissions - corporate bonds, sector-based emission factors
A2: Financed emissions = (outstanding / EVIC) x revenue x sector EF. PCAF score 4 = reported revenue, 5 = revenue estimated from the sector revenue/EVIC proxy.
A4: Holding ID | B4: Portfolio sector | C4: Outstanding ($M) | D4: EVIC ($M) | E4: Attribution factor | F4: Revenue basis | G4: Revenue used ($M) | H4: Sector EF (t/$M) | I4: Financed emissions (tCO2e) | J4: PCAF data-quality score | K4: Portfolio weight | L4: WACI contribution (t/$M) | N4: Portfolio sector | O4: Holdings | P4: Outstanding ($M) | Q4: Financed emissions (tCO2e) | R4: Share of financed emissions | S4: Weighted PCAF score | T4: Carbon footprint (t/$M invested)
A5: =Holdings!A2 | B5: =Holdings!C2 | C5: =Holdings!F2 | D5: =Holdings!G2 | E5: =C5/D5 | F5: =IF(ISBLANK(Holdings!H2),"Sector proxy","Reported") | G5: =IF(ISBLANK(Holdings!H2),D5*VLOOKUP(B5,Inputs!$A$15:$B$36,2,FALSE),Holdings!H2) | H5: =_xlfn.XLOOKUP(B5,'Emission Factors'!$G$5:$G$26,'Emission Factors'!$H$5:$H$26) | I5: =E5*G5*H5 | J5: =IF(ISBLANK(Holdings!H2),5,4) | K5: =C5/SUM($C$5:$C$304) | L5: =K5*H5 | N5: Oil & Gas Producers | O5: =COUNTIF($B$5:$B$304,N5) | P5: =SUMIFS($C$5:$C$304,$B$5:$B$304,N5) | Q5: =SUMIFS($I$5:$I$304,$B$5:$B$304,N5) | R5: =Q5/SUM($Q$5:$Q$26) | S5: =SUMPRODUCT(($B$5:$B$304=N5)*$C$5:$C$304*$J$5:$J$304)/P5 | T5: =Q5/P5
A6: =Holdings!A3 | B6: =Holdings!C3 | C6: =Holdings!F3 | D6: =Holdings!G3 | E6: =C6/D6 | F6: =IF(ISBLANK(Holdings!H3),"Sector proxy","Reported") | G6: =IF(ISBLANK(Holdings!H3),D6*VLOOKUP(B6,Inputs!$A$15:$B$36,2,FALSE),Holdings!H3) | H6: =_xlfn.XLOOKUP(B6,'Emission Factors'!$G$5:$G$26,'Emission Factors'!$H$5:$H$26) | I6: =E6*G6*H6 | J6: =IF(ISBLANK(Holdings!H3),5,4) | K6: =C6/SUM($C$5:$C$304) | L6: =K6*H6 | N6: Petroleum Refining | O6: =COUNTIF($B$5:$B$304,N6) | P6: =SUMIFS($C$5:$C$304,$B$5:$B$304,N6) | Q6: =SUMIFS($I$5:$I$304,$B$5:$B$304,N6) | R6: =Q6/SUM($Q$5:$Q$26) | S6: =SUMPRODUCT(($B$5:$B$304=N6)*$C$5:$C$304*$J$5:$J$304)/P6 | T6: =Q6/P6
A7: =Holdings!A4 | B7: =Holdings!C4 | C7: =Holdings!F4 | D7: =Holdings!G4 | E7: =C7/D7 | F7: =IF(ISBLANK(Holdings!H4),"Sector proxy","Reported") | G7: =IF(ISBLANK(Holdings!H4),D7*VLOOKUP(B7,Inputs!$A$15:$B$36,2,FALSE),Holdings!H4) | H7: =_xlfn.XLOOKUP(B7,'Emission Factors'!$G$5:$G$26,'Emission Factors'!$H$5:$H$26) | I7: =E7*G7*H7 | J7: =IF(ISBLANK(Holdings!H4),5,4) | K7: =C7/SUM($C$5:$C$304) | L7: =K7*H7 | N7: Pipelines | O7: =COUNTIF($B$5:$B$304,N7) | P7: =SUMIFS($C$5:$C$304,$B$5:$B$304,N7) | Q7: =SUMIFS($I$5:$I$304,$B$5:$B$304,N7) | R7: =Q7/SUM($Q$5:$Q$26) | S7: =SUMPRODUCT(($B$5:$B$304=N7)*$C$5:$C$304*$J$5:$J$304)/P7 | T7: =Q7/P7
A8: =Holdings!A5 | B8: =Holdings!C5 | C8: =Holdings!F5 | D8: =Holdings!G5 | E8: =C8/D8 | F8: =IF(ISBLANK(Holdings!H5),"Sector proxy","Reported") | G8: =IF(ISBLANK(Holdings!H5),D8*VLOOKUP(B8,Inputs!$A$15:$B$36,2,FALSE),Holdings!H5) | H8: =_xlfn.XLOOKUP(B8,'Emission Factors'!$G$5:$G$26,'Emission Factors'!$H$5:$H$26) | I8: =E8*G8*H8 | J8: =IF(ISBLANK(Holdings!H5),5,4) | K8: =C8/SUM($C$5:$C$304) | L8: =K8*H8 | N8: Electric Utilities | O8: =COUNTIF($B$5:$B$304,N8) | P8: =SUMIFS($C$5:$C$304,$B$5:$B$304,N8) | Q8: =SUMIFS($I$5:$I$304,$B$5:$B$304,N8) | R8: =Q8/SUM($Q$5:$Q$26) | S8: =SUMPRODUCT(($B$5:$B$304=N8)*$C$5:$C$304*$J$5:$J$304)/P8 | T8: =Q8/P8
A9: =Holdings!A6 | B9: =Holdings!C6 | C9: =Holdings!F6 | D9: =Holdings!G6 | E9: =C9/D9 | F9: =IF(ISBLANK(Holdings!H6),"Sector proxy","Reported") | G9: =IF(ISBLANK(Holdings!H6),D9*VLOOKUP(B9,Inputs!$A$15:$B$36,2,FALSE),Holdings!H6) | H9: =_xlfn.XLOOKUP(B9,'Emission Factors'!$G$5:$G$26,'Emission Factors'!$H$5:$H$26) | I9: =E9*G9*H9 | J9: =IF(ISBLANK(Holdings!H6),5,4) | K9: =C9/SUM($C$5:$C$304) | L9: =K9*H9 | N9: Gas Distribution & Water | O9: =COUNTIF($B$5:$B$304,N9) | P9: =SUMIFS($C$5:$C$304,$B$5:$B$304,N9) | Q9: =SUMIFS($I$5:$I$304,$B$5:$B$304,N9) | R9: =Q9/SUM($Q$5:$Q$26) | S9: =SUMPRODUCT(($B$5:$B$304=N9)*$C$5:$C$304*$J$5:$J$304)/P9 | T9: =Q9/P9
A10: =Holdings!A7 | B10: =Holdings!C7 | C10: =Holdings!F7 | D10: =Holdings!G7 | E10: =C10/D10 | F10: =IF(ISBLANK(Holdings!H7),"Sector proxy","Reported") | G10: =IF(ISBLANK(Holdings!H7),D10*VLOOKUP(B10,Inputs!$A$15:$B$36,2,FALSE),Holdings!H7) | H10: =_xlfn.XLOOKUP(B10,'Emission Factors'!$G$5:$G$26,'Emission Factors'!$H$5:$H$26) | I10: =E10*G10*H10 | J10: =IF(ISBLANK(Holdings!H7),5,4) | K10: =C10/SUM($C$5:$C$304) | L10: =K10*H10 | N10: Mining & Quarrying | O10: =COUNTIF($B$5:$B$304,N10) | P10: =SUMIFS($C$5:$C$304,$B$5:$B$304,N10) | Q10: =SUMIFS($I$5:$I$304,$B$5:$B$304,N10) | R10: =Q10/SUM($Q$5:$Q$26) | S10: =SUMPRODUCT(($B$5:$B$304=N10)*$C$5:$C$304*$J$5:$J$304)/P10 | T10: =Q10/P10
A11: =Holdings!A8 | B11: =Holdings!C8 | C11: =Holdings!F8 | D11: =Holdings!G8 | E11: =C11/D11 | F11: =IF(ISBLANK(Holdings!H8),"Sector proxy","Reported") | G11: =IF(ISBLANK(Holdings!H8),D11*VLOOKUP(B11,Inputs!$A$15:$B$36,2,FALSE),Holdings!H8) | H11: =_xlfn.XLOOKUP(B11,'Emission Factors'!$G$5:$G$26,'Emission Factors'!$H$5:$H$26) | I11: =E11*G11*H11 | J11: =IF(ISBLANK(Holdings!H8),5,4) | K11: =C11/SUM($C$5:$C$304) | L11: =K11*H11 | N11: Cement & Building Materials | O11: =COUNTIF($B$5:$B$304,N11) | P11: =SUMIFS($C$5:$C$304,$B$5:$B$304,N11) | Q11: =SUMIFS($I$5:$I$304,$B$5:$B$304,N11) | R11: =Q11/SUM($Q$5:$Q$26) | S11: =SUMPRODUCT(($B$5:$B$304=N11)*$C$5:$C$304*$J$5:$J$304)/P11 | T11: =Q11/P11
A12: =Holdings!A9 | B12: =Holdings!C9 | C12: =Holdings!F9 | D12: =Holdings!G9 | E12: =C12/D12 | F12: =IF(ISBLANK(Holdings!H9),"Sector proxy","Reported") | G12: =IF(ISBLANK(Holdings!H9),D12*VLOOKUP(B12,Inputs!$A$15:$B$36,2,FALSE),Holdings!H9) | H12: =_xlfn.XLOOKUP(B12,'Emission Factors'!$G$5:$G$26,'Emission Factors'!$H$5:$H$26) | I12: =E12*G12*H12 | J12: =IF(ISBLANK(Holdings!H9),5,4) | K12: =C12/SUM($C$5:$C$304) | L12: =K12*H12 | N12: Metals & Steel | O12: =COUNTIF($B$5:$B$304,N12) | P12: =SUMIFS($C$5:$C$304,$B$5:$B$304,N12) | Q12: =SUMIFS($I$5:$I$304,$B$5:$B$304,N12) | R12: =Q12/SUM($Q$5:$Q$26) | S12: =SUMPRODUCT(($B$5:$B$304=N12)*$C$5:$C$304*$J$5:$J$304)/P12 | T12: =Q12/P12
A13: =Holdings!A10 | B13: =Holdings!C10 | C13: =Holdings!F10 | D13: =Holdings!G10 | E13: =C13/D13 | F13: =IF(ISBLANK(Holdings!H10),"Sector proxy","Reported") | G13: =IF(ISBLANK(Holdings!H10),D13*VLOOKUP(B13,Inputs!$A$15:$B$36,2,FALSE),Holdings!H10) | H13: =_xlfn.XLOOKUP(B13,'Emission Factors'!$G$5:$G$26,'Emission Factors'!$H$5:$H$26) | I13: =E13*G13*H13 | J13: =IF(ISBLANK(Holdings!H10),5,4) | K13: =C13/SUM($C$5:$C$304) | L13: =K13*H13 | N13: Chemicals & Plastics | O13: =COUNTIF($B$5:$B$304,N13) | P13: =SUMIFS($C$5:$C$304,$B$5:$B$304,N13) | Q13: =SUMIFS($I$5:$I$304,$B$5:$B$304,N13) | R13: =Q13/SUM($Q$5:$Q$26) | S13: =SUMPRODUCT(($B$5:$B$304=N13)*$C$5:$C$304*$J$5:$J$304)/P13 | T13: =Q13/P13
A14: =Holdings!A11 | B14: =Holdings!C11 | C14: =Holdings!F11 | D14: =Holdings!G11 | E14: =C14/D14 | F14: =IF(ISBLANK(Holdings!H11),"Sector proxy","Reported") | G14: =IF(ISBLANK(Holdings!H11),D14*VLOOKUP(B14,Inputs!$A$15:$B$36,2,FALSE),Holdings!H11) | H14: =_xlfn.XLOOKUP(B14,'Emission Factors'!$G$5:$G$26,'Emission Factors'!$H$5:$H$26) | I14: =E14*G14*H14 | J14: =IF(ISBLANK(Holdings!H11),5,4) | K14: =C14/SUM($C$5:$C$304) | L14: =K14*H14 | N14: Forest & Paper Products | O14: =COUNTIF($B$5:$B$304,N14) | P14: =SUMIFS($C$5:$C$304,$B$5:$B$304,N14) | Q14: =SUMIFS($I$5:$I$304,$B$5:$B$304,N14) | R14: =Q14/SUM($Q$5:$Q$26) | S14: =SUMPRODUCT(($B$5:$B$304=N14)*$C$5:$C$304*$J$5:$J$304)/P14 | T14: =Q14/P14
A15: =Holdings!A12 | B15: =Holdings!C12 | C15: =Holdings!F12 | D15: =Holdings!G12 | E15: =C15/D15 | F15: =IF(ISBLANK(Holdings!H12),"Sector proxy","Reported") | G15: =IF(ISBLANK(Holdings!H12),D15*VLOOKUP(B15,Inputs!$A$15:$B$36,2,FALSE),Holdings!H12) | H15: =_xlfn.XLOOKUP(B15,'Emission Factors'!$G$5:$G$26,'Emission Factors'!$H$5:$H$26) | I15: =E15*G15*H15 | J15: =IF(ISBLANK(Holdings!H12),5,4) | K15: =C15/SUM($C$5:$C$304) | L15: =K15*H15 | N15: Agriculture & Food | O15: =COUNTIF($B$5:$B$304,N15) | P15: =SUMIFS($C$5:$C$304,$B$5:$B$304,N15) | Q15: =SUMIFS($I$5:$I$304,$B$5:$B$304,N15) | R15: =Q15/SUM($Q$5:$Q$26) | S15: =SUMPRODUCT(($B$5:$B$304=N15)*$C$5:$C$304*$J$5:$J$304)/P15 | T15: =Q15/P15
A16: =Holdings!A13 | B16: =Holdings!C13 | C16: =Holdings!F13 | D16: =Holdings!G13 | E16: =C16/D16 | F16: =IF(ISBLANK(Holdings!H13),"Sector proxy","Reported") | G16: =IF(ISBLANK(Holdings!H13),D16*VLOOKUP(B16,Inputs!$A$15:$B$36,2,FALSE),Holdings!H13) | H16: =_xlfn.XLOOKUP(B16,'Emission Factors'!$G$5:$G$26,'Emission Factors'!$H$5:$H$26) | I16: =E16*G16*H16 | J16: =IF(ISBLANK(Holdings!H13),5,4) | K16: =C16/SUM($C$5:$C$304) | L16: =K16*H16 | N16: Airlines | O16: =COUNTIF($B$5:$B$304,N16) | P16: =SUMIFS($C$5:$C$304,$B$5:$B$304,N16) | Q16: =SUMIFS($I$5:$I$304,$B$5:$B$304,N16) | R16: =Q16/SUM($Q$5:$Q$26) | S16: =SUMPRODUCT(($B$5:$B$304=N16)*$C$5:$C$304*$J$5:$J$304)/P16 | T16: =Q16/P16
... A26: =Holdings!A23 | B26: =Holdings!C23 | C26: =Holdings!F23 | D26: =Holdings!G23 | E26: =C26/D26 | F26: =IF(ISBLANK(Holdings!H23),"Sector proxy","Reported") | G26: =IF(ISBLANK(Holdings!H23),D26*VLOOKUP(B26,Inputs!$A$15:$B$36,2,FALSE),Holdings!H23) | H26: =_xlfn.XLOOKUP(B26,'Emission Factors'!$G$5:$G$26,'Emission Factors'!$H$5:$H$26) | I26: =E26*G26*H26 | J26: =IF(ISBLANK(Holdings!H23),5,4) | K26: =C26/SUM($C$5:$C$304) | L26: =K26*H26 | N26: Business & Consumer Services | O26: =COUNTIF($B$5:$B$304,N26) | P26: =SUMIFS($C$5:$C$304,$B$5:$B$304,N26) | Q26: =SUMIFS($I$5:$I$304,$B$5:$B$304,N26) | R26: =Q26/SUM($Q$5:$Q$26) | S26: =SUMPRODUCT(($B$5:$B$304=N26)*$C$5:$C$304*$J$5:$J$304)/P26 | T26: =Q26/P26
A27: =Holdings!A24 | B27: =Holdings!C24 | C27: =Holdings!F24 | D27: =Holdings!G24 | E27: =C27/D27 | F27: =IF(ISBLANK(Holdings!H24),"Sector proxy","Reported") | G27: =IF(ISBLANK(Holdings!H24),D27*VLOOKUP(B27,Inputs!$A$15:$B$36,2,FALSE),Holdings!H24) | H27: =_xlfn.XLOOKUP(B27,'Emission Factors'!$G$5:$G$26,'Emission Factors'!$H$5:$H$26) | I27: =E27*G27*H27 | J27: =IF(ISBLANK(Holdings!H24),5,4) | K27: =C27/SUM($C$5:$C$304) | L27: =K27*H27 | N27: Total portfolio | O27: =SUM(O5:O26) | P27: =SUM(P5:P26) | Q27: =SUM(Q5:Q26) | R27: =SUM(R5:R26) | S27: =SUMPRODUCT($C$5:$C$304,$J$5:$J$304)/SUM($C$5:$C$304) | T27: =Q27/P27
A28: =Holdings!A25 | B28: =Holdings!C25 | C28: =Holdings!F25 | D28: =Holdings!G25 | E28: =C28/D28 | F28: =IF(ISBLANK(Holdings!H25),"Sector proxy","Reported") | G28: =IF(ISBLANK(Holdings!H25),D28*VLOOKUP(B28,Inputs!$A$15:$B$36,2,FALSE),Holdings!H25) | H28: =_xlfn.XLOOKUP(B28,'Emission Factors'!$G$5:$G$26,'Emission Factors'!$H$5:$H$26) | I28: =E28*G28*H28 | J28: =IF(ISBLANK(Holdings!H25),5,4) | K28: =C28/SUM($C$5:$C$304) | L28: =K28*H28
A29: =Holdings!A26 | B29: =Holdings!C26 | C29: =Holdings!F26 | D29: =Holdings!G26 | E29: =C29/D29 | F29: =IF(ISBLANK(Holdings!H26),"Sector proxy","Reported") | G29: =IF(ISBLANK(Holdings!H26),D29*VLOOKUP(B29,Inputs!$A$15:$B$36,2,FALSE),Holdings!H26) | H29: =_xlfn.XLOOKUP(B29,'Emission Factors'!$G$5:$G$26,'Emission Factors'!$H$5:$H$26) | I29: =E29*G29*H29 | J29: =IF(ISBLANK(Holdings!H26),5,4) | K29: =C29/SUM($C$5:$C$304) | L29: =K29*H29
A30: =Holdings!A27 | B30: =Holdings!C27 | C30: =Holdings!F27 | D30: =Holdings!G27 | E30: =C30/D30 | F30: =IF(ISBLANK(Holdings!H27),"Sector proxy","Reported") | G30: =IF(ISBLANK(Holdings!H27),D30*VLOOKUP(B30,Inputs!$A$15:$B$36,2,FALSE),Holdings!H27) | H30: =_xlfn.XLOOKUP(B30,'Emission Factors'!$G$5:$G$26,'Emission Factors'!$H$5:$H$26) | I30: =E30*G30*H30 | J30: =IF(ISBLANK(Holdings!H27),5,4) | K30: =C30/SUM($C$5:$C$304) | L30: =K30*H30
A31: =Holdings!A28 | B31: =Holdings!C28 | C31: =Holdings!F28 | D31: =Holdings!G28 | E31: =C31/D31 | F31: =IF(ISBLANK(Holdings!H28),"Sector proxy","Reported") | G31: =IF(ISBLANK(Holdings!H28),D31*VLOOKUP(B31,Inputs!$A$15:$B$36,2,FALSE),Holdings!H28) | H31: =_xlfn.XLOOKUP(B31,'Emission Factors'!$G$5:$G$26,'Emission Factors'!$H$5:$H$26) | I31: =E31*G31*H31 | J31: =IF(ISBLANK(Holdings!H28),5,4) | K31: =C31/SUM($C$5:$C$304) | L31: =K31*H31
A32: =Holdings!A29 | B32: =Holdings!C29 | C32: =Holdings!F29 | D32: =Holdings!G29 | E32: =C32/D32 | F32: =IF(ISBLANK(Holdings!H29),"Sector proxy","Reported") | G32: =IF(ISBLANK(Holdings!H29),D32*VLOOKUP(B32,Inputs!$A$15:$B$36,2,FALSE),Holdings!H29) | H32: =_xlfn.XLOOKUP(B32,'Emission Factors'!$G$5:$G$26,'Emission Factors'!$H$5:$H$26) | I32: =E32*G32*H32 | J32: =IF(ISBLANK(Holdings!H29),5,4) | K32: =C32/SUM($C$5:$C$304) | L32: =K32*H32
A33: =Holdings!A30 | B33: =Holdings!C30 | C33: =Holdings!F30 | D33: =Holdings!G30 | E33: =C33/D33 | F33: =IF(ISBLANK(Holdings!H30),"Sector proxy","Reported") | G33: =IF(ISBLANK(Holdings!H30),D33*VLOOKUP(B33,Inputs!$A$15:$B$36,2,FALSE),Holdings!H30) | H33: =_xlfn.XLOOKUP(B33,'Emission Factors'!$G$5:$G$26,'Emission Factors'!$H$5:$H$26) | I33: =E33*G33*H33 | J33: =IF(ISBLANK(Holdings!H30),5,4) | K33: =C33/SUM($C$5:$C$304) | L33: =K33*H33
A34: =Holdings!A31 | B34: =Holdings!C31 | C34: =Holdings!F31 | D34: =Holdings!G31 | E34: =C34/D34 | F34: =IF(ISBLANK(Holdings!H31),"Sector proxy","Reported") | G34: =IF(ISBLANK(Holdings!H31),D34*VLOOKUP(B34,Inputs!$A$15:$B$36,2,FALSE),Holdings!H31) | H34: =_xlfn.XLOOKUP(B34,'Emission Factors'!$G$5:$G$26,'Emission Factors'!$H$5:$H$26) | I34: =E34*G34*H34 | J34: =IF(ISBLANK(Holdings!H31),5,4) | K34: =C34/SUM($C$5:$C$304) | L34: =K34*H34
A35: =Holdings!A32 | B35: =Holdings!C32 | C35: =Holdings!F32 | D35: =Holdings!G32 | E35: =C35/D35 | F35: =IF(ISBLANK(Holdings!H32),"Sector proxy","Reported") | G35: =IF(ISBLANK(Holdings!H32),D35*VLOOKUP(B35,Inputs!$A$15:$B$36,2,FALSE),Holdings!H32) | H35: =_xlfn.XLOOKUP(B35,'Emission Factors'!$G$5:$G$26,'Emission Factors'!$H$5:$H$26) | I35: =E35*G35*H35 | J35: =IF(ISBLANK(Holdings!H32),5,4) | K35: =C35/SUM($C$5:$C$304) | L35: =K35*H35
A36: =Holdings!A33 | B36: =Holdings!C33 | C36: =Holdings!F33 | D36: =Holdings!G33 | E36: =C36/D36 | F36: =IF(ISBLANK(Holdings!H33),"Sector proxy","Reported") | G36: =IF(ISBLANK(Holdings!H33),D36*VLOOKUP(B36,Inputs!$A$15:$B$36,2,FALSE),Holdings!H33) | H36: =_xlfn.XLOOKUP(B36,'Emission Factors'!$G$5:$G$26,'Emission Factors'!$H$5:$H$26) | I36: =E36*G36*H36 | J36: =IF(ISBLANK(Holdings!H33),5,4) | K36: =C36/SUM($C$5:$C$304) | L36: =K36*H36
A37: =Holdings!A34 | B37: =Holdings!C34 | C37: =Holdings!F34 | D37: =Holdings!G34 | E37: =C37/D37 | F37: =IF(ISBLANK(Holdings!H34),"Sector proxy","Reported") | G37: =IF(ISBLANK(Holdings!H34),D37*VLOOKUP(B37,Inputs!$A$15:$B$36,2,FALSE),Holdings!H34) | H37: =_xlfn.XLOOKUP(B37,'Emission Factors'!$G$5:$G$26,'Emission Factors'!$H$5:$H$26) | I37: =E37*G37*H37 | J37: =IF(ISBLANK(Holdings!H34),5,4) | K37: =C37/SUM($C$5:$C$304) | L37: =K37*H37
A38: =Holdings!A35 | B38: =Holdings!C35 | C38: =Holdings!F35 | D38: =Holdings!G35 | E38: =C38/D38 | F38: =IF(ISBLANK(Holdings!H35),"Sector proxy","Reported") | G38: =IF(ISBLANK(Holdings!H35),D38*VLOOKUP(B38,Inputs!$A$15:$B$36,2,FALSE),Holdings!H35) | H38: =_xlfn.XLOOKUP(B38,'Emission Factors'!$G$5:$G$26,'Emission Factors'!$H$5:$H$26) | I38: =E38*G38*H38 | J38: =IF(ISBLANK(Holdings!H35),5,4) | K38: =C38/SUM($C$5:$C$304) | L38: =K38*H38
A39: =Holdings!A36 | B39: =Holdings!C36 | C39: =Holdings!F36 | D39: =Holdings!G36 | E39: =C39/D39 | F39: =IF(ISBLANK(Holdings!H36),"Sector proxy","Reported") | G39: =IF(ISBLANK(Holdings!H36),D39*VLOOKUP(B39,Inputs!$A$15:$B$36,2,FALSE),Holdings!H36) | H39: =_xlfn.XLOOKUP(B39,'Emission Factors'!$G$5:$G$26,'Emission Factors'!$H$5:$H$26) | I39: =E39*G39*H39 | J39: =IF(ISBLANK(Holdings!H36),5,4) | K39: =C39/SUM($C$5:$C$304) | L39: =K39*H39
... A304: =Holdings!A301 | B304: =Holdings!C301 | C304: =Holdings!F301 | D304: =Holdings!G301 | E304: =C304/D304 | F304: =IF(ISBLANK(Holdings!H301),"Sector proxy","Reported") | G304: =IF(ISBLANK(Holdings!H301),D304*VLOOKUP(B304,Inputs!$A$15:$B$36,2,FALSE),Holdings!H301) | H304: =_xlfn.XLOOKUP(B304,'Emission Factors'!$G$5:$G$26,'Emission Factors'!$H$5:$H$26) | I304: =E304*G304*H304 | J304: =IF(ISBLANK(Holdings!H301),5,4) | K304: =C304/SUM($C$5:$C$304) | L304: =K304*H304

Sheet WACI
A1: Weighted average carbon intensity (tCO2e per $M revenue)
A2: WACI = sum over holdings of portfolio weight x issuer carbon intensity; with sector EFs the issuer intensity equals the sector EF.
A4: Portfolio sector | B4: Portfolio weight | C4: Sector EF (t/$M) | D4: WACI contribution (t/$M)
A5: Oil & Gas Producers | B5: =SUMIFS('Financed Emissions'!$C$5:$C$304,'Financed Emissions'!$B$5:$B$304,A5)/SUM('Financed Emissions'!$C$5:$C$304) | C5: =INDEX('Emission Factors'!$H$5:$H$26,MATCH(A5,'Emission Factors'!$G$5:$G$26,0)) | D5: =B5*C5
A6: Petroleum Refining | B6: =SUMIFS('Financed Emissions'!$C$5:$C$304,'Financed Emissions'!$B$5:$B$304,A6)/SUM('Financed Emissions'!$C$5:$C$304) | C6: =INDEX('Emission Factors'!$H$5:$H$26,MATCH(A6,'Emission Factors'!$G$5:$G$26,0)) | D6: =B6*C6
A7: Pipelines | B7: =SUMIFS('Financed Emissions'!$C$5:$C$304,'Financed Emissions'!$B$5:$B$304,A7)/SUM('Financed Emissions'!$C$5:$C$304) | C7: =INDEX('Emission Factors'!$H$5:$H$26,MATCH(A7,'Emission Factors'!$G$5:$G$26,0)) | D7: =B7*C7
A8: Electric Utilities | B8: =SUMIFS('Financed Emissions'!$C$5:$C$304,'Financed Emissions'!$B$5:$B$304,A8)/SUM('Financed Emissions'!$C$5:$C$304) | C8: =INDEX('Emission Factors'!$H$5:$H$26,MATCH(A8,'Emission Factors'!$G$5:$G$26,0)) | D8: =B8*C8
A9: Gas Distribution & Water | B9: =SUMIFS('Financed Emissions'!$C$5:$C$304,'Financed Emissions'!$B$5:$B$304,A9)/SUM('Financed Emissions'!$C$5:$C$304) | C9: =INDEX('Emission Factors'!$H$5:$H$26,MATCH(A9,'Emission Factors'!$G$5:$G$26,0)) | D9: =B9*C9
A10: Mining & Quarrying | B10: =SUMIFS('Financed Emissions'!$C$5:$C$304,'Financed Emissions'!$B$5:$B$304,A10)/SUM('Financed Emissions'!$C$5:$C$304) | C10: =INDEX('Emission Factors'!$H$5:$H$26,MATCH(A10,'Emission Factors'!$G$5:$G$26,0)) | D10: =B10*C10
A11: Cement & Building Materials | B11: =SUMIFS('Financed Emissions'!$C$5:$C$304,'Financed Emissions'!$B$5:$B$304,A11)/SUM('Financed Emissions'!$C$5:$C$304) | C11: =INDEX('Emission Factors'!$H$5:$H$26,MATCH(A11,'Emission Factors'!$G$5:$G$26,0)) | D11: =B11*C11
A12: Metals & Steel | B12: =SUMIFS('Financed Emissions'!$C$5:$C$304,'Financed Emissions'!$B$5:$B$304,A12)/SUM('Financed Emissions'!$C$5:$C$304) | C12: =INDEX('Emission Factors'!$H$5:$H$26,MATCH(A12,'Emission Factors'!$G$5:$G$26,0)) | D12: =B12*C12
A13: Chemicals & Plastics | B13: =SUMIFS('Financed Emissions'!$C$5:$C$304,'Financed Emissions'!$B$5:$B$304,A13)/SUM('Financed Emissions'!$C$5:$C$304) | C13: =INDEX('Emission Factors'!$H$5:$H$26,MATCH(A13,'Emission Factors'!$G$5:$G$26,0)) | D13: =B13*C13
A14: Forest & Paper Products | B14: =SUMIFS('Financed Emissions'!$C$5:$C$304,'Financed Emissions'!$B$5:$B$304,A14)/SUM('Financed Emissions'!$C$5:$C$304) | C14: =INDEX('Emission Factors'!$H$5:$H$26,MATCH(A14,'Emission Factors'!$G$5:$G$26,0)) | D14: =B14*C14
A15: Agriculture & Food | B15: =SUMIFS('Financed Emissions'!$C$5:$C$304,'Financed Emissions'!$B$5:$B$304,A15)/SUM('Financed Emissions'!$C$5:$C$304) | C15: =INDEX('Emission Factors'!$H$5:$H$26,MATCH(A15,'Emission Factors'!$G$5:$G$26,0)) | D15: =B15*C15
A16: Airlines | B16: =SUMIFS('Financed Emissions'!$C$5:$C$304,'Financed Emissions'!$B$5:$B$304,A16)/SUM('Financed Emissions'!$C$5:$C$304) | C16: =INDEX('Emission Factors'!$H$5:$H$26,MATCH(A16,'Emission Factors'!$G$5:$G$26,0)) | D16: =B16*C16
... A26: Business & Consumer Services | B26: =SUMIFS('Financed Emissions'!$C$5:$C$304,'Financed Emissions'!$B$5:$B$304,A26)/SUM('Financed Emissions'!$C$5:$C$304) | C26: =INDEX('Emission Factors'!$H$5:$H$26,MATCH(A26,'Emission Factors'!$G$5:$G$26,0)) | D26: =B26*C26
A27: Total | B27: =SUM(B5:B26) | D27: =SUM(D5:D26)
A29: WACI, sector roll-up (t/$M revenue) | B29: =SUMPRODUCT(B5:B26,C5:C26)
A30: WACI, holding level (t/$M revenue) | B30: =SUM('Financed Emissions'!$L$5:$L$304)
A31: Carbon footprint (tCO2e per $M invested) | B31: ='Financed Emissions'!Q27/'Financed Emissions'!P27
A32: Total financed emissions (tCO2e) | B32: ='Financed Emissions'!Q27

Sheet Benchmark Comparison
A1: Peer benchmark: portfolio vs economy-weighted benchmark
A2: Benchmark weights = each sector's share of Canadian gross output in the reporting year (StatCan 36-10-0488-01).
A4: Portfolio sector | B4: Portfolio weight | C4: Benchmark weight | D4: Sector EF (t/$M) | E4: Portfolio WACI contribution | F4: Benchmark WACI contribution | G4: Active weight | H4: Contribution difference | I4: Allocation effect
A5: Oil & Gas Producers | B5: =WACI!B5 | C5: =VLOOKUP(A5,'Emission Factors'!$G$5:$I$26,3,FALSE)/SUM('Emission Factors'!$I$5:$I$26) | D5: =WACI!C5 | E5: =B5*D5 | F5: =C5*D5 | G5: =B5-C5 | H5: =E5-F5 | I5: =G5*(D5-$B$30)
A6: Petroleum Refining | B6: =WACI!B6 | C6: =VLOOKUP(A6,'Emission Factors'!$G$5:$I$26,3,FALSE)/SUM('Emission Factors'!$I$5:$I$26) | D6: =WACI!C6 | E6: =B6*D6 | F6: =C6*D6 | G6: =B6-C6 | H6: =E6-F6 | I6: =G6*(D6-$B$30)
A7: Pipelines | B7: =WACI!B7 | C7: =VLOOKUP(A7,'Emission Factors'!$G$5:$I$26,3,FALSE)/SUM('Emission Factors'!$I$5:$I$26) | D7: =WACI!C7 | E7: =B7*D7 | F7: =C7*D7 | G7: =B7-C7 | H7: =E7-F7 | I7: =G7*(D7-$B$30)
A8: Electric Utilities | B8: =WACI!B8 | C8: =VLOOKUP(A8,'Emission Factors'!$G$5:$I$26,3,FALSE)/SUM('Emission Factors'!$I$5:$I$26) | D8: =WACI!C8 | E8: =B8*D8 | F8: =C8*D8 | G8: =B8-C8 | H8: =E8-F8 | I8: =G8*(D8-$B$30)
A9: Gas Distribution & Water | B9: =WACI!B9 | C9: =VLOOKUP(A9,'Emission Factors'!$G$5:$I$26,3,FALSE)/SUM('Emission Factors'!$I$5:$I$26) | D9: =WACI!C9 | E9: =B9*D9 | F9: =C9*D9 | G9: =B9-C9 | H9: =E9-F9 | I9: =G9*(D9-$B$30)
A10: Mining & Quarrying | B10: =WACI!B10 | C10: =VLOOKUP(A10,'Emission Factors'!$G$5:$I$26,3,FALSE)/SUM('Emission Factors'!$I$5:$I$26) | D10: =WACI!C10 | E10: =B10*D10 | F10: =C10*D10 | G10: =B10-C10 | H10: =E10-F10 | I10: =G10*(D10-$B$30)
A11: Cement & Building Materials | B11: =WACI!B11 | C11: =VLOOKUP(A11,'Emission Factors'!$G$5:$I$26,3,FALSE)/SUM('Emission Factors'!$I$5:$I$26) | D11: =WACI!C11 | E11: =B11*D11 | F11: =C11*D11 | G11: =B11-C11 | H11: =E11-F11 | I11: =G11*(D11-$B$30)
A12: Metals & Steel | B12: =WACI!B12 | C12: =VLOOKUP(A12,'Emission Factors'!$G$5:$I$26,3,FALSE)/SUM('Emission Factors'!$I$5:$I$26) | D12: =WACI!C12 | E12: =B12*D12 | F12: =C12*D12 | G12: =B12-C12 | H12: =E12-F12 | I12: =G12*(D12-$B$30)
A13: Chemicals & Plastics | B13: =WACI!B13 | C13: =VLOOKUP(A13,'Emission Factors'!$G$5:$I$26,3,FALSE)/SUM('Emission Factors'!$I$5:$I$26) | D13: =WACI!C13 | E13: =B13*D13 | F13: =C13*D13 | G13: =B13-C13 | H13: =E13-F13 | I13: =G13*(D13-$B$30)
A14: Forest & Paper Products | B14: =WACI!B14 | C14: =VLOOKUP(A14,'Emission Factors'!$G$5:$I$26,3,FALSE)/SUM('Emission Factors'!$I$5:$I$26) | D14: =WACI!C14 | E14: =B14*D14 | F14: =C14*D14 | G14: =B14-C14 | H14: =E14-F14 | I14: =G14*(D14-$B$30)
A15: Agriculture & Food | B15: =WACI!B15 | C15: =VLOOKUP(A15,'Emission Factors'!$G$5:$I$26,3,FALSE)/SUM('Emission Factors'!$I$5:$I$26) | D15: =WACI!C15 | E15: =B15*D15 | F15: =C15*D15 | G15: =B15-C15 | H15: =E15-F15 | I15: =G15*(D15-$B$30)
A16: Airlines | B16: =WACI!B16 | C16: =VLOOKUP(A16,'Emission Factors'!$G$5:$I$26,3,FALSE)/SUM('Emission Factors'!$I$5:$I$26) | D16: =WACI!C16 | E16: =B16*D16 | F16: =C16*D16 | G16: =B16-C16 | H16: =E16-F16 | I16: =G16*(D16-$B$30)
... A26: Business & Consumer Services | B26: =WACI!B26 | C26: =VLOOKUP(A26,'Emission Factors'!$G$5:$I$26,3,FALSE)/SUM('Emission Factors'!$I$5:$I$26) | D26: =WACI!C26 | E26: =B26*D26 | F26: =C26*D26 | G26: =B26-C26 | H26: =E26-F26 | I26: =G26*(D26-$B$30)
A27: Total | B27: =SUM(B5:B26) | C27: =SUM(C5:C26) | E27: =SUM(E5:E26) | F27: =SUM(F5:F26) | G27: =SUM(G5:G26) | H27: =SUM(H5:H26) | I27: =SUM(I5:I26)
A29: Portfolio WACI (t/$M revenue) | B29: =SUM(E5:E26)
A30: Benchmark WACI (t/$M revenue) | B30: =SUM(F5:F26)
A31: Portfolio vs benchmark | B31: =B29/B30-1

Sheet Carbon Price Scenarios
A1: Transition-risk stress: carbon cost on financed emissions
A2: Cost = financed emissions x carbon price x (1 - free allocation share). Emissions held at the reporting-year level (a static balance sheet, not a forecast). Edit prices on the Inputs tab.
A4: Effective price ($/t after free allocation) | B4: =Inputs!B8 | C4: =Inputs!C8 | D4: =Inputs!D8 | E4: =Inputs!E8 | F4: =Inputs!F8 | G4: =Inputs!G8 | H4: =Inputs!H8 | I4: Free allocation share
A5: =Inputs!A9 | B5: =Inputs!B9*(1-Inputs!$I$9) | C5: =Inputs!C9*(1-Inputs!$I$9) | D5: =Inputs!D9*(1-Inputs!$I$9) | E5: =Inputs!E9*(1-Inputs!$I$9) | F5: =Inputs!F9*(1-Inputs!$I$9) | G5: =Inputs!G9*(1-Inputs!$I$9) | H5: =Inputs!H9*(1-Inputs!$I$9) | I5: =Inputs!I9
A6: =Inputs!A10 | B6: =Inputs!B10*(1-Inputs!$I$10) | C6: =Inputs!C10*(1-Inputs!$I$10) | D6: =Inputs!D10*(1-Inputs!$I$10) | E6: =Inputs!E10*(1-Inputs!$I$10) | F6: =Inputs!F10*(1-Inputs!$I$10) | G6: =Inputs!G10*(1-Inputs!$I$10) | H6: =Inputs!H10*(1-Inputs!$I$10) | I6: =Inputs!I10
A7: =Inputs!A11 | B7: =Inputs!B11*(1-Inputs!$I$11) | C7: =Inputs!C11*(1-Inputs!$I$11) | D7: =Inputs!D11*(1-Inputs!$I$11) | E7: =Inputs!E11*(1-Inputs!$I$11) | F7: =Inputs!F11*(1-Inputs!$I$11) | G7: =Inputs!G11*(1-Inputs!$I$11) | H7: =Inputs!H11*(1-Inputs!$I$11) | I7: =Inputs!I11
A10: Carbon cost ($M CAD) | B10: =Inputs!B8 | C10: =Inputs!C8 | D10: =Inputs!D8 | E10: =Inputs!E8 | F10: =Inputs!F8 | G10: =Inputs!G8 | H10: =Inputs!H8
A11: =Inputs!A9 | B11: ='Financed Emissions'!$Q$27*B5/1000000 | C11: ='Financed Emissions'!$Q$27*C5/1000000 | D11: ='Financed Emissions'!$Q$27*D5/1000000 | E11: ='Financed Emissions'!$Q$27*E5/1000000 | F11: ='Financed Emissions'!$Q$27*F5/1000000 | G11: ='Financed Emissions'!$Q$27*G5/1000000 | H11: ='Financed Emissions'!$Q$27*H5/1000000
A12: =Inputs!A10 | B12: ='Financed Emissions'!$Q$27*B6/1000000 | C12: ='Financed Emissions'!$Q$27*C6/1000000 | D12: ='Financed Emissions'!$Q$27*D6/1000000 | E12: ='Financed Emissions'!$Q$27*E6/1000000 | F12: ='Financed Emissions'!$Q$27*F6/1000000 | G12: ='Financed Emissions'!$Q$27*G6/1000000 | H12: ='Financed Emissions'!$Q$27*H6/1000000
A13: =Inputs!A11 | B13: ='Financed Emissions'!$Q$27*B7/1000000 | C13: ='Financed Emissions'!$Q$27*C7/1000000 | D13: ='Financed Emissions'!$Q$27*D7/1000000 | E13: ='Financed Emissions'!$Q$27*E7/1000000 | F13: ='Financed Emissions'!$Q$27*F7/1000000 | G13: ='Financed Emissions'!$Q$27*G7/1000000 | H13: ='Financed Emissions'!$Q$27*H7/1000000
A16: Carbon cost as % of holdings | B16: =Inputs!B8 | C16: =Inputs!C8 | D16: =Inputs!D8 | E16: =Inputs!E8 | F16: =Inputs!F8 | G16: =Inputs!G8 | H16: =Inputs!H8
A17: =Inputs!A9 | B17: =B11/'Financed Emissions'!$P$27 | C17: =C11/'Financed Emissions'!$P$27 | D17: =D11/'Financed Emissions'!$P$27 | E17: =E11/'Financed Emissions'!$P$27 | F17: =F11/'Financed Emissions'!$P$27 | G17: =G11/'Financed Emissions'!$P$27 | H17: =H11/'Financed Emissions'!$P$27
A18: =Inputs!A10 | B18: =B12/'Financed Emissions'!$P$27 | C18: =C12/'Financed Emissions'!$P$27 | D18: =D12/'Financed Emissions'!$P$27 | E18: =E12/'Financed Emissions'!$P$27 | F18: =F12/'Financed Emissions'!$P$27 | G18: =G12/'Financed Emissions'!$P$27 | H18: =H12/'Financed Emissions'!$P$27
A19: =Inputs!A11 | B19: =B13/'Financed Emissions'!$P$27 | C19: =C13/'Financed Emissions'!$P$27 | D19: =D13/'Financed Emissions'!$P$27 | E19: =E13/'Financed Emissions'!$P$27 | F19: =F13/'Financed Emissions'!$P$27 | G19: =G13/'Financed Emissions'!$P$27 | H19: =H13/'Financed Emissions'!$P$27
A21: Sector carbon cost in the headline year (Inputs!B5) | C21: Carbon cost ($M CAD) | F21: Cost as % of sector holdings
A22: Portfolio sector | B22: Financed emissions (tCO2e) | C22: =Inputs!A9 | D22: =Inputs!A10 | E22: =Inputs!A11 | F22: =Inputs!A9 | G22: =Inputs!A10 | H22: =Inputs!A11
A23: Oil & Gas Producers | B23: ='Financed Emissions'!Q5 | C23: =B23*INDEX(Inputs!$B$9:$H$11,MATCH(C$22,Inputs!$A$9:$A$11,0),MATCH(Inputs!$B$5,Inputs!$B$8:$H$8,0))*(1-INDEX(Inputs!$I$9:$I$11,MATCH(C$22,Inputs!$A$9:$A$11,0)))/1000000 | D23: =B23*INDEX(Inputs!$B$9:$H$11,MATCH(D$22,Inputs!$A$9:$A$11,0),MATCH(Inputs!$B$5,Inputs!$B$8:$H$8,0))*(1-INDEX(Inputs!$I$9:$I$11,MATCH(D$22,Inputs!$A$9:$A$11,0)))/1000000 | E23: =B23*INDEX(Inputs!$B$9:$H$11,MATCH(E$22,Inputs!$A$9:$A$11,0),MATCH(Inputs!$B$5,Inputs!$B$8:$H$8,0))*(1-INDEX(Inputs!$I$9:$I$11,MATCH(E$22,Inputs!$A$9:$A$11,0)))/1000000 | F23: =C23/'Financed Emissions'!P5 | G23: =D23/'Financed Emissions'!P5 | H23: =E23/'Financed Emissions'!P5
A24: Petroleum Refining | B24: ='Financed Emissions'!Q6 | C24: =B24*INDEX(Inputs!$B$9:$H$11,MATCH(C$22,Inputs!$A$9:$A$11,0),MATCH(Inputs!$B$5,Inputs!$B$8:$H$8,0))*(1-INDEX(Inputs!$I$9:$I$11,MATCH(C$22,Inputs!$A$9:$A$11,0)))/1000000 | D24: =B24*INDEX(Inputs!$B$9:$H$11,MATCH(D$22,Inputs!$A$9:$A$11,0),MATCH(Inputs!$B$5,Inputs!$B$8:$H$8,0))*(1-INDEX(Inputs!$I$9:$I$11,MATCH(D$22,Inputs!$A$9:$A$11,0)))/1000000 | E24: =B24*INDEX(Inputs!$B$9:$H$11,MATCH(E$22,Inputs!$A$9:$A$11,0),MATCH(Inputs!$B$5,Inputs!$B$8:$H$8,0))*(1-INDEX(Inputs!$I$9:$I$11,MATCH(E$22,Inputs!$A$9:$A$11,0)))/1000000 | F24: =C24/'Financed Emissions'!P6 | G24: =D24/'Financed Emissions'!P6 | H24: =E24/'Financed Emissions'!P6
A25: Pipelines | B25: ='Financed Emissions'!Q7 | C25: =B25*INDEX(Inputs!$B$9:$H$11,MATCH(C$22,Inputs!$A$9:$A$11,0),MATCH(Inputs!$B$5,Inputs!$B$8:$H$8,0))*(1-INDEX(Inputs!$I$9:$I$11,MATCH(C$22,Inputs!$A$9:$A$11,0)))/1000000 | D25: =B25*INDEX(Inputs!$B$9:$H$11,MATCH(D$22,Inputs!$A$9:$A$11,0),MATCH(Inputs!$B$5,Inputs!$B$8:$H$8,0))*(1-INDEX(Inputs!$I$9:$I$11,MATCH(D$22,Inputs!$A$9:$A$11,0)))/1000000 | E25: =B25*INDEX(Inputs!$B$9:$H$11,MATCH(E$22,Inputs!$A$9:$A$11,0),MATCH(Inputs!$B$5,Inputs!$B$8:$H$8,0))*(1-INDEX(Inputs!$I$9:$I$11,MATCH(E$22,Inputs!$A$9:$A$11,0)))/1000000 | F25: =C25/'Financed Emissions'!P7 | G25: =D25/'Financed Emissions'!P7 | H25: =E25/'Financed Emissions'!P7
A26: Electric Utilities | B26: ='Financed Emissions'!Q8 | C26: =B26*INDEX(Inputs!$B$9:$H$11,MATCH(C$22,Inputs!$A$9:$A$11,0),MATCH(Inputs!$B$5,Inputs!$B$8:$H$8,0))*(1-INDEX(Inputs!$I$9:$I$11,MATCH(C$22,Inputs!$A$9:$A$11,0)))/1000000 | D26: =B26*INDEX(Inputs!$B$9:$H$11,MATCH(D$22,Inputs!$A$9:$A$11,0),MATCH(Inputs!$B$5,Inputs!$B$8:$H$8,0))*(1-INDEX(Inputs!$I$9:$I$11,MATCH(D$22,Inputs!$A$9:$A$11,0)))/1000000 | E26: =B26*INDEX(Inputs!$B$9:$H$11,MATCH(E$22,Inputs!$A$9:$A$11,0),MATCH(Inputs!$B$5,Inputs!$B$8:$H$8,0))*(1-INDEX(Inputs!$I$9:$I$11,MATCH(E$22,Inputs!$A$9:$A$11,0)))/1000000 | F26: =C26/'Financed Emissions'!P8 | G26: =D26/'Financed Emissions'!P8 | H26: =E26/'Financed Emissions'!P8
A27: Gas Distribution & Water | B27: ='Financed Emissions'!Q9 | C27: =B27*INDEX(Inputs!$B$9:$H$11,MATCH(C$22,Inputs!$A$9:$A$11,0),MATCH(Inputs!$B$5,Inputs!$B$8:$H$8,0))*(1-INDEX(Inputs!$I$9:$I$11,MATCH(C$22,Inputs!$A$9:$A$11,0)))/1000000 | D27: =B27*INDEX(Inputs!$B$9:$H$11,MATCH(D$22,Inputs!$A$9:$A$11,0),MATCH(Inputs!$B$5,Inputs!$B$8:$H$8,0))*(1-INDEX(Inputs!$I$9:$I$11,MATCH(D$22,Inputs!$A$9:$A$11,0)))/1000000 | E27: =B27*INDEX(Inputs!$B$9:$H$11,MATCH(E$22,Inputs!$A$9:$A$11,0),MATCH(Inputs!$B$5,Inputs!$B$8:$H$8,0))*(1-INDEX(Inputs!$I$9:$I$11,MATCH(E$22,Inputs!$A$9:$A$11,0)))/1000000 | F27: =C27/'Financed Emissions'!P9 | G27: =D27/'Financed Emissions'!P9 | H27: =E27/'Financed Emissions'!P9
A28: Mining & Quarrying | B28: ='Financed Emissions'!Q10 | C28: =B28*INDEX(Inputs!$B$9:$H$11,MATCH(C$22,Inputs!$A$9:$A$11,0),MATCH(Inputs!$B$5,Inputs!$B$8:$H$8,0))*(1-INDEX(Inputs!$I$9:$I$11,MATCH(C$22,Inputs!$A$9:$A$11,0)))/1000000 | D28: =B28*INDEX(Inputs!$B$9:$H$11,MATCH(D$22,Inputs!$A$9:$A$11,0),MATCH(Inputs!$B$5,Inputs!$B$8:$H$8,0))*(1-INDEX(Inputs!$I$9:$I$11,MATCH(D$22,Inputs!$A$9:$A$11,0)))/1000000 | E28: =B28*INDEX(Inputs!$B$9:$H$11,MATCH(E$22,Inputs!$A$9:$A$11,0),MATCH(Inputs!$B$5,Inputs!$B$8:$H$8,0))*(1-INDEX(Inputs!$I$9:$I$11,MATCH(E$22,Inputs!$A$9:$A$11,0)))/1000000 | F28: =C28/'Financed Emissions'!P10 | G28: =D28/'Financed Emissions'!P10 | H28: =E28/'Financed Emissions'!P10
A29: Cement & Building Materials | B29: ='Financed Emissions'!Q11 | C29: =B29*INDEX(Inputs!$B$9:$H$11,MATCH(C$22,Inputs!$A$9:$A$11,0),MATCH(Inputs!$B$5,Inputs!$B$8:$H$8,0))*(1-INDEX(Inputs!$I$9:$I$11,MATCH(C$22,Inputs!$A$9:$A$11,0)))/1000000 | D29: =B29*INDEX(Inputs!$B$9:$H$11,MATCH(D$22,Inputs!$A$9:$A$11,0),MATCH(Inputs!$B$5,Inputs!$B$8:$H$8,0))*(1-INDEX(Inputs!$I$9:$I$11,MATCH(D$22,Inputs!$A$9:$A$11,0)))/1000000 | E29: =B29*INDEX(Inputs!$B$9:$H$11,MATCH(E$22,Inputs!$A$9:$A$11,0),MATCH(Inputs!$B$5,Inputs!$B$8:$H$8,0))*(1-INDEX(Inputs!$I$9:$I$11,MATCH(E$22,Inputs!$A$9:$A$11,0)))/1000000 | F29: =C29/'Financed Emissions'!P11 | G29: =D29/'Financed Emissions'!P11 | H29: =E29/'Financed Emissions'!P11
A30: Metals & Steel | B30: ='Financed Emissions'!Q12 | C30: =B30*INDEX(Inputs!$B$9:$H$11,MATCH(C$22,Inputs!$A$9:$A$11,0),MATCH(Inputs!$B$5,Inputs!$B$8:$H$8,0))*(1-INDEX(Inputs!$I$9:$I$11,MATCH(C$22,Inputs!$A$9:$A$11,0)))/1000000 | D30: =B30*INDEX(Inputs!$B$9:$H$11,MATCH(D$22,Inputs!$A$9:$A$11,0),MATCH(Inputs!$B$5,Inputs!$B$8:$H$8,0))*(1-INDEX(Inputs!$I$9:$I$11,MATCH(D$22,Inputs!$A$9:$A$11,0)))/1000000 | E30: =B30*INDEX(Inputs!$B$9:$H$11,MATCH(E$22,Inputs!$A$9:$A$11,0),MATCH(Inputs!$B$5,Inputs!$B$8:$H$8,0))*(1-INDEX(Inputs!$I$9:$I$11,MATCH(E$22,Inputs!$A$9:$A$11,0)))/1000000 | F30: =C30/'Financed Emissions'!P12 | G30: =D30/'Financed Emissions'!P12 | H30: =E30/'Financed Emissions'!P12
A31: Chemicals & Plastics | B31: ='Financed Emissions'!Q13 | C31: =B31*INDEX(Inputs!$B$9:$H$11,MATCH(C$22,Inputs!$A$9:$A$11,0),MATCH(Inputs!$B$5,Inputs!$B$8:$H$8,0))*(1-INDEX(Inputs!$I$9:$I$11,MATCH(C$22,Inputs!$A$9:$A$11,0)))/1000000 | D31: =B31*INDEX(Inputs!$B$9:$H$11,MATCH(D$22,Inputs!$A$9:$A$11,0),MATCH(Inputs!$B$5,Inputs!$B$8:$H$8,0))*(1-INDEX(Inputs!$I$9:$I$11,MATCH(D$22,Inputs!$A$9:$A$11,0)))/1000000 | E31: =B31*INDEX(Inputs!$B$9:$H$11,MATCH(E$22,Inputs!$A$9:$A$11,0),MATCH(Inputs!$B$5,Inputs!$B$8:$H$8,0))*(1-INDEX(Inputs!$I$9:$I$11,MATCH(E$22,Inputs!$A$9:$A$11,0)))/1000000 | F31: =C31/'Financed Emissions'!P13 | G31: =D31/'Financed Emissions'!P13 | H31: =E31/'Financed Emissions'!P13
A32: Forest & Paper Products | B32: ='Financed Emissions'!Q14 | C32: =B32*INDEX(Inputs!$B$9:$H$11,MATCH(C$22,Inputs!$A$9:$A$11,0),MATCH(Inputs!$B$5,Inputs!$B$8:$H$8,0))*(1-INDEX(Inputs!$I$9:$I$11,MATCH(C$22,Inputs!$A$9:$A$11,0)))/1000000 | D32: =B32*INDEX(Inputs!$B$9:$H$11,MATCH(D$22,Inputs!$A$9:$A$11,0),MATCH(Inputs!$B$5,Inputs!$B$8:$H$8,0))*(1-INDEX(Inputs!$I$9:$I$11,MATCH(D$22,Inputs!$A$9:$A$11,0)))/1000000 | E32: =B32*INDEX(Inputs!$B$9:$H$11,MATCH(E$22,Inputs!$A$9:$A$11,0),MATCH(Inputs!$B$5,Inputs!$B$8:$H$8,0))*(1-INDEX(Inputs!$I$9:$I$11,MATCH(E$22,Inputs!$A$9:$A$11,0)))/1000000 | F32: =C32/'Financed Emissions'!P14 | G32: =D32/'Financed Emissions'!P14 | H32: =E32/'Financed Emissions'!P14
A33: Agriculture & Food | B33: ='Financed Emissions'!Q15 | C33: =B33*INDEX(Inputs!$B$9:$H$11,MATCH(C$22,Inputs!$A$9:$A$11,0),MATCH(Inputs!$B$5,Inputs!$B$8:$H$8,0))*(1-INDEX(Inputs!$I$9:$I$11,MATCH(C$22,Inputs!$A$9:$A$11,0)))/1000000 | D33: =B33*INDEX(Inputs!$B$9:$H$11,MATCH(D$22,Inputs!$A$9:$A$11,0),MATCH(Inputs!$B$5,Inputs!$B$8:$H$8,0))*(1-INDEX(Inputs!$I$9:$I$11,MATCH(D$22,Inputs!$A$9:$A$11,0)))/1000000 | E33: =B33*INDEX(Inputs!$B$9:$H$11,MATCH(E$22,Inputs!$A$9:$A$11,0),MATCH(Inputs!$B$5,Inputs!$B$8:$H$8,0))*(1-INDEX(Inputs!$I$9:$I$11,MATCH(E$22,Inputs!$A$9:$A$11,0)))/1000000 | F33: =C33/'Financed Emissions'!P15 | G33: =D33/'Financed Emissions'!P15 | H33: =E33/'Financed Emissions'!P15
A34: Airlines | B34: ='Financed Emissions'!Q16 | C34: =B34*INDEX(Inputs!$B$9:$H$11,MATCH(C$22,Inputs!$A$9:$A$11,0),MATCH(Inputs!$B$5,Inputs!$B$8:$H$8,0))*(1-INDEX(Inputs!$I$9:$I$11,MATCH(C$22,Inputs!$A$9:$A$11,0)))/1000000 | D34: =B34*INDEX(Inputs!$B$9:$H$11,MATCH(D$22,Inputs!$A$9:$A$11,0),MATCH(Inputs!$B$5,Inputs!$B$8:$H$8,0))*(1-INDEX(Inputs!$I$9:$I$11,MATCH(D$22,Inputs!$A$9:$A$11,0)))/1000000 | E34: =B34*INDEX(Inputs!$B$9:$H$11,MATCH(E$22,Inputs!$A$9:$A$11,0),MATCH(Inputs!$B$5,Inputs!$B$8:$H$8,0))*(1-INDEX(Inputs!$I$9:$I$11,MATCH(E$22,Inputs!$A$9:$A$11,0)))/1000000 | F34: =C34/'Financed Emissions'!P16 | G34: =D34/'Financed Emissions'!P16 | H34: =E34/'Financed Emissions'!P16
... A44: Business & Consumer Services | B44: ='Financed Emissions'!Q26 | C44: =B44*INDEX(Inputs!$B$9:$H$11,MATCH(C$22,Inputs!$A$9:$A$11,0),MATCH(Inputs!$B$5,Inputs!$B$8:$H$8,0))*(1-INDEX(Inputs!$I$9:$I$11,MATCH(C$22,Inputs!$A$9:$A$11,0)))/1000000 | D44: =B44*INDEX(Inputs!$B$9:$H$11,MATCH(D$22,Inputs!$A$9:$A$11,0),MATCH(Inputs!$B$5,Inputs!$B$8:$H$8,0))*(1-INDEX(Inputs!$I$9:$I$11,MATCH(D$22,Inputs!$A$9:$A$11,0)))/1000000 | E44: =B44*INDEX(Inputs!$B$9:$H$11,MATCH(E$22,Inputs!$A$9:$A$11,0),MATCH(Inputs!$B$5,Inputs!$B$8:$H$8,0))*(1-INDEX(Inputs!$I$9:$I$11,MATCH(E$22,Inputs!$A$9:$A$11,0)))/1000000 | F44: =C44/'Financed Emissions'!P26 | G44: =D44/'Financed Emissions'!P26 | H44: =E44/'Financed Emissions'!P26
A45: Total | B45: =SUM(B23:B44) | C45: =SUM(C23:C44) | D45: =SUM(D23:D44) | E45: =SUM(E23:E44) | F45: =C45/'Financed Emissions'!P27 | G45: =D45/'Financed Emissions'!P27 | H45: =E45/'Financed Emissions'!P27

Sheet Reconciliation
A1: Reconciliation to published StatCan totals (table 38-10-0097-01)
A2: Industry rows are rounded to 1 kt, so the sum may drift from the total by up to 0.5 kt per row. The NIR gap reflects the residence (account) vs territorial (inventory) basis.
A4: Year | B4: Industry rows | C4: Sum of industry rows (kt) | D4: Published total, industries (kt) | E4: Difference (kt) | F4: Rounding tolerance (kt) | G4: Result | H4: Industries + households (kt) | I4: NIR / UNFCCC total (kt) | J4: Gap to NIR (kt) | K4: Published bridge (kt) | L4: Unexplained residual (kt)
A5: 2009 | B5: =COUNTIFS('StatCan GHG'!$A$2:$A$1692,A5) | C5: =SUMIFS('StatCan GHG'!$D$2:$D$1692,'StatCan GHG'!$A$2:$A$1692,A5) | D5: =INDEX('StatCan Totals'!$B$2:$B$16,MATCH(A5,'StatCan Totals'!$A$2:$A$16,0)) | E5: =C5-D5 | F5: =B5*0.5 | G5: =IF(ABS(E5)<=F5,"PASS","FAIL") | H5: =INDEX('StatCan Totals'!$D$2:$D$16,MATCH(A5,'StatCan Totals'!$A$2:$A$16,0)) | I5: =INDEX('StatCan Totals'!$E$2:$E$16,MATCH(A5,'StatCan Totals'!$A$2:$A$16,0)) | J5: =I5-H5 | K5: =INDEX('StatCan Totals'!$F$2:$F$16,MATCH(A5,'StatCan Totals'!$A$2:$A$16,0)) | L5: =J5-K5
